Workbook

Sheet Tabla 6 (3)

Sheet Vinilos EBM
A1: Nº | B1: Portada | C1: TÍTULO | D1: ARTISTA | E1: AÑO | F1: GÉNERO | G1: TIPO EDICIÓN | H1: FECHA | I1: LUGAR COMPRA | J1: PRECIO COMPRA | K1: PREICO ACTUAL | L1: DIFERENCIA | M1: Total | O1: Observaciones
A2: 1 | C2: Let It Bleed | D2: The Rolling Stones | E2: 1969 | F2: Rock Internacional | G2: Repress | H2: 45215 | I2: Fetén | J2: 30 | K2: 23.9 | L2: =--SUBSTITUTE(J2," €","") - K2 -> 6.1 | M2: =SUM(L2:L304) -> -1139.669 | N2: Diferencia
A3: 2 | C3: The Darkside of the Moon | D3: Pink Floyd | E3: 1972 | F3: Rock Internacional | G3: Redición (50º An) | H3: 45215 | I3: Amazon Esp | J3: 21.5 | K3: =ColumnaPrecios!C2 -> 47,99 | L3: =--SUBSTITUTE(J3," €","") - K3 -> -26.49
A4: 3 | C4: At Newport | D4: Muddy Waters | E4: 1960 | F4: Blues | G4: Reedición | H4: 45215 | I4: Amazon Esp | J4: 14.5 | K4: =ColumnaPrecios!C4 -> 14,99 | L4: =--SUBSTITUTE(J4," €","") - K4 -> -0.49 | M4: =SUM(J2:J501) -> 3017.127 | N4: Pagado
A5: 4 | C5: The Simon and Garfunkel Collection Sus obras maestras | D5: Simon and Garfunkel | E5: 1981 | F5: Cantautor/Folk | G5: Original (1981) | H5: 45217 | I5: Fetén | J5: 15 | K5: 11 | L5: =--SUBSTITUTE(J5," €","") - K5 -> 4
A6: 5 | C6: Are you Experienced? | D6: Jimi Hendrix Experience | E6: 1967 | F6: Rock Internacional | G6: Reedición | H6: 45229 | I6: Rock Y Pop (Turin) | J6: 26.9 | K6: =ColumnaPrecios!B6 -> 31,99 | L6: =--SUBSTITUTE(J6," €","") - K6 -> -5.09
A7: 6 | C7: The Ziggy Stardust and The Spiders From Mars | D7: David Bowie | E7: 1972 | F7: Rock Internacional | G7: Reedición | H7: 45256 | I7: Freebird Records (Dublin) | J7: 22.95 | K7: =ColumnaPrecios!C8 -> 24,74 | L7: =--SUBSTITUTE(J7," €","") - K7 -> -1.79
A8: 7 | C8: Communique | D8: Dire Straits | E8: 1979 | F8: Rock Internacional | G8: Original (Hol) | H8: 45231 | I8: Feria Disco Salamanca | J8: 20 | K8: 25 | L8: =--SUBSTITUTE(J8," €","") - K8 -> -5
A9: 8 | C9: Texas Flood | D9: Stevie Ray Vaughan | E9: 1983 | F9: Blues | G9: Original (Esp) | H9: 45231 | I9: Feria Disco Salamanca | J9: 25 | K9: 31 | L9: =--SUBSTITUTE(J9," €","") - K9 -> -6
A10: 9 | C10: Dedicado a Antonio Machado, poeta | D10: J.M. Serrat | E10: 1969 | F10: Cantautor/Folk | G10: Original (Esp) | H10: 45261 | I10: Fetén | J10: 15 | K10: 9 | L10: =--SUBSTITUTE(J10," €","") - K10 -> 6
A11: 10 | C11: Exile on Main Street | D11: The Rolling Stones | E11: 1972 | F11: Rock Internacional | G11: Reedición | H11: 45313 | I11: Amazon Esp | J11: 28.97 | K11: =ExileOnMain!A2 -> 45.99 | L11: =--SUBSTITUTE(J11," €","") - K11 -> -17.02
A12: 11 | C12: Let It Be | D12: The Beatles | E12: 1970 | F12: Rock Internacional | G12: Reedición (50º An) | H12: 45313 | I12: Amazon Esp | J12: 21.99 | K12: =ColumnaPrecios!B10 -> 34,99 | L12: =--SUBSTITUTE(J12," €","") - K12 -> -13
A13: 12 | C13: Time Out | D13: Brubeck Quartet | E13: 1959 | F13: Jazz | G13: Reedición | H13: 45313 | I13: Amazon Esp | J13: 11.99 | K13: =ColumnaPrecios!B12 -> 14,50 | L13: =--SUBSTITUTE(J13," €","") - K13 -> -2.51
A14: 13 | C14: Innuendo | D14: Queen | E14: 1991 | F14: Rock Internacional | G14: Reedicion? | H14: 45292 | I14: Amazon Esp | J14: 30 | K14: 40 | L14: =--SUBSTITUTE(J14," €","") - K14 -> -10
A15: 14 | C15: Enseñanzas de la Historia | D15: Carlos Puebla y los Tradicionales | E15: 1977 | F15: Latina | G15: Original (Esp) | H15: 45323 | I15: Fetén | J15: 10 | K15: 10 | L15: =--SUBSTITUTE(J15," €","") - K15 -> 0
A16: 15 | C16: The Best Of Muddy Waters | D16: Muddy Waters | E16: 1958 | F16: Blues | G16: Reedición | H16: 45329 | I16: Amazon Esp | J16: 14 | K16: =ColumnaPrecios!B14 -> 18,98 | L16: =--SUBSTITUTE(J16," €","") - K16 -> -4.98
A17: 16 | C17: Y en Eso Llegó Fidel | D17: Carlos Puebla y los Tradicionales | E17: 1976 | F17: Latina | G17: Original (Esp) | H17: 45352 | I17: Fetén | J17: 20 | K17: 12 | L17: =--SUBSTITUTE(J17," €","") - K17 -> 8
A18: 17 | C18: Songs From A Room | D18: Leonard Cohen | E18: 1969 | F18: Cantautor/Folk | G18: Reedición | H18: 45352 | I18: Amazon Esp | J18: 9.99 | K18: =SongFromARoom!A2 -> 27,37 | L18: =--SUBSTITUTE(J18," €","") - K18 -> -17.38
A19: 18 | C19: Con Cariño y con Cuidado | D19: Valeria Castro | E19: 2023 | F19: Cantautor/Folk | G19: Original Firmado | H19: 45373 | I19: Al Artista | J19: 25 | K19: 28.5 | L19: =--SUBSTITUTE(J19," €","") - K19 -> -3.5 | O19: Firmado por Valeria a la salida del concierto en en el Teatro del Liceo de Salamanca
A20: 19 | C20: Unplugged | D20: Eric Clapton | E20: 1992 | F20: Rock Internacional | G20: Reedición | H20: 45387 | I20: Amazon Esp | J20: 35.18 | K20: =UnpluggedClapton!A2 -> 41,71 | L20: =--SUBSTITUTE(J20," €","") - K20 -> -6.53
A21: 20 | C21: Mediterráneo | D21: J.M. Serrat | E21: 1971 | F21: Cantautor/Folk | G21: Original | H21: 45383 | I21: Feten | J21: 20 | K21: 14 | L21: =--SUBSTITUTE(J21," €","") - K21 -> 6
A22: 21 | C22: Vinicius de Moraes en La Fusa | D22: Vinicius de Moraes, María Creuza y Toquinho | E22: 1974 | F22: Latina | G22: Original | H22: 45409 | I22: La Metralleta | J22: 7 | K22: 10 | L22: =--SUBSTITUTE(J22," €","") - K22 -> -3 | O22: Daño en la portada
A23: 22 | C23: Tiempo de Cerezas | D23: Víctor Manuel | E23: 1989 | F23: Cantautor/Folk | G23: Original | H23: 45409 | I23: La Metralleta | J23: 7 | K23: 6 | L23: =--SUBSTITUTE(J23," €","") - K23 -> 1 | O23: Regalo a Elizabeth por el día de la madre
A24: 23 | C24: Different Class | D24: Pulp | E24: 1995 | F24: Rock Internacional | G24: Reedición | H24: 45409 | I24: La Metralleta | J24: 28 | K24: =ColumnaPrecios!B16 -> 26,99 | L24: =--SUBSTITUTE(J24," €","") - K24 -> 1.01
A25: 24 | C25: Santana Grandes Éxitos | D25: Santana | E25: 1974 | F25: Rock Internacional | G25: Reedicion Esp1983 | H25: 45413 | I25: Fetén | J25: 20 | K25: 14 | L25: =--SUBSTITUTE(J25," €","") - K25 -> 6
A26: 25 | C26: Rubber Soul | D26: The Beatles | E26: 1965 | F26: Rock Internacional | G26: Reedicion | H26: 45436 | I26: Amazon Esp | J26: 26.44 | K26: 31.99 | L26: =--SUBSTITUTE(J26," €","") - K26 -> -5.55
A27: 26 | C27: Bringing It All Back Home | D27: Bob Dylan | E27: 1964 | F27: Cantautor/Folk | G27: Reedición | H27: 45436 | I27: Amazon Esp | J27: 15.69 | K27: 27.4 | L27: =--SUBSTITUTE(J27," €","") - K27 -> -11.71
A28: 27 | C28: Cheap Thrills | D28: Big Brother & The Holding Company (Janis Joplin) | E28: 1968 | F28: Rock Internacional | G28: Reedición | H28: 45436 | I28: Amazon Esp | J28: 15.69 | K28: 30.54 | L28: =--SUBSTITUTE(J28," €","") - K28 -> -14.85
A29: 28 | C29: Buena Vista Social Club | D29: Buena Vista Social Club | E29: 1997 | F29: Latina | G29: Reedición | H29: 45436 | I29: Amazon Esp | J29: 24.78 | K29: 34.99 | L29: =--SUBSTITUTE(J29," €","") - K29 -> -10.21
A30: 29 | C30: Tapestry | D30: Carole King | E30: 1971 | F30: Cantautor/Folk | G30: Reedición | H30: 45481 | I30: Amazon Esp | J30: 14.24 | K30: 23.88 | L30: =--SUBSTITUTE(J30," €","") - K30 -> -9.64
A31: 30 | C31: Highway 61 Revisted | D31: Bob Dylan | E31: 1965 | F31: Cantautor/Folk | G31: Reedición | H31: 45481 | I31: Amazon Esp | J31: 14.24 | K31: 21.99 | L31: =--SUBSTITUTE(J31," €","") - K31 -> -7.75
A32: 31 | C32: Born in the USA | D32: Bruce Springsteen | E32: 1984 | F32: Rock Internacional | G32: Reedición | H32: 45481 | I32: Amazon Esp | J32: 13.49 | K32: 21.99 | L32: =--SUBSTITUTE(J32," €","") - K32 -> -8.5
A33: 32 | C33: Abbey Road | D33: The Beatles | E33: 1969 | F33: Rock Internacional | G33: Reedición | H33: 45481 | I33: Amazon Esp | J33: 28.89 | K33: 31.99 | L33: =--SUBSTITUTE(J33," €","") - K33 -> -3.1
A34: 33 | C34: Lo Mejor de los Cream | D34: Cream | E34: 1969 | F34: Rock Internacional | G34: Original ESP (1969) | H34: 45585 | I34: Feria Disco Salamanca | J34: 12 | K34: 12 | L34: =--SUBSTITUTE(J34," €","") - K34 -> 0
A35: 34 | C35: Automatic For The People | D35: REM | E35: 1992 | F35: Rock Internacional | G35: Reedición (25ª Aniversario) | H35: 45591 | I35: Amazon Esp | J35: 20.99 | K35: 31.8 | L35: =--SUBSTITUTE(J35," €","") - K35 -> -10.81
A36: 35 | C36: Unknown Pleasures | D36: Joy Division | E36: 1979 | F36: Rock Internacional | G36: Reedición | H36: 45597 | I36: Amazon Esp | J36: 18 | K36: 20.99 | L36: =--SUBSTITUTE(J36," €","") - K36 -> -2.99
... A43: 42 | C43: I´m Your Man | D43: Leonard Cohen | E43: 1988 | F43: Cantautor/Folk | G43: Reedicion | H43: 45634 | I43: Fnac Paris | J43: 16 | K43: 29.65 | L43: =--SUBSTITUTE(J43," €","") - K43 -> -13.65
A44: 43 | C44: Transa | D44: Caetano Veloso | E44: 1972 | F44: Latina | G44: Reedicion | H44: 45663 | I44: Hey Boy Hey Girl (La Laguna) | J44: 28 | K44: 28.98 | L44: =--SUBSTITUTE(J44," €","") - K44 -> -0.98 | O44: Regalo de Reyes de Elizabeth
A45: 44 | C45: What´s The Story Morning Glory | D45: Oasis | E45: 1995 | F45: Rock Internacional | G45: Reedicion | H45: 45679 | I45: Amazon Esp | J45: 28.79 | K45: 47.27 | L45: =--SUBSTITUTE(J45," €","") - K45 -> -18.48 | O45: Reyes Tía Angu
A46: 45 | C46: Celia & Johnny | D46: Celia Cruz & Johnny Pacheco | E46: 1974 | F46: Latina | G46: Reedicion | H46: 45679 | I46: Amazon Esp | J46: 29.69 | K46: 38.75 | L46: =--SUBSTITUTE(J46," €","") - K46 -> -9.06 | O46: Reyes Padrino y Madrina
...

Sheet ColumnaPrecios
A1: Dark Side | B1: Column2 | C1: Column3 | D1: Column4
A2: Disco de vinilo, LP Doble, 13 octubre 2023 "Vuelva a intentarlo" | B2: — | C2: 47,99 | D2: —
A3: At Newport | B3: Column2 | C3: Column3 | D3: Column4
A4: Disco de vinilo, Importación, 13 abril 2017 | B4: 14,99 € | C4: 14,99 | D4: —
A5: Are you Experienced | B5: Column2 | C5: Column3 | D5: Column4
A6: Disco de vinilo, Importación, 9 octubre 2015 "Vuelva a intentarlo" | B6: 31,99 | C6: 31,99 € | D6: 25,81 €
A7: Ziggy Stardust | B7: Column2 | C7: Column3
A8: Disco de vinilo, 26 febrero 2016 "Vuelva a intentarlo" | B8: — | C8: 24,74
A9: Let it Be | B9: Column2 | C9: Column3 | D9: Column4
A10: Disco de vinilo, LP Doble, 15 octubre 2021 "Vuelva a intentarlo" | B10: 34,99 | C10: 34,45 € | D10: —
A11: Time Out | B11: Column2 | C11: Column3 | D11: Column4
A12: Disco de vinilo, Grabación original remasterizada, 16 marzo 2017 "Vuelva a intentarlo" | B12: 14,50 | C12: 14,50 € | D12: —
A13: The Besto Muddy Waters | B13: Column2 | C13: Column3 | D13: Column4
A14: Disco de vinilo "Vuelva a intentarlo" | B14: 18,98 | C14: 18,98 € | D14: —
A15: Column1 | B15: Column2 | C15: Column3 | D15: Column4
A16: Disco de vinilo, Importación, 1 diciembre 2015 "Vuelva a intentarlo" | B16: 26,99 | C16: 26,99 | D16: —

Sheet ExileOnMain
A1: Column1 | B1: Column2 | C1: Column3
A2: 45.99 | B2: 45 | C2: 99
A3: 45.99 | B3: 45 | C3: 99
A4: 14.27 | B4: 14 | C4: 27
A5: 19.99 | B5: 19 | C5: 99
A6: 16.85 | B6: 16 | C6: 85
A7: 39.99 | B7: 39 | C7: 99
A8: 22.99 | B8: 22 | C8: 99
A9: 34.99 | B9: 34 | C9: 99
A10: 277.18 | B10: 277 | C10: 18
A11: 22.99 | B11: 22 | C11: 99
A12: 34.99 | B12: 34 | C12: 99
A13: 29.99 | B13: 29 | C13: 99
... A16: 19.99 | B16: 19 | C16: 99

Sheet SongFromARoom
A1: Column1 | B1: Column2 | C1: Column3
A2: 27,37 | B2: 27 | C2: 37
A3: 27,37 | B3: 27 | C3: 37
A4: 18,71 | B4: 18 | C4: 71
A5: 16,99 | B5: 16 | C5: 99
A6: 16,99 | B6: 16 | C6: 99
A7: 16,99 | B7: 16 | C7: 99
A8: 22,99 | B8: 22 | C8: 99
A9: 277,18 | B9: 277 | C9: 18
A10: 16,99 | B10: 16 | C10: 99
A11: 277,18 | B11: 277 | C11: 18
A12: 36,99 | B12: 36 | C12: 99
A13: 22,99 | B13: 22 | C13: 99
... A16: 28,99 | B16: 28 | C16: 99

Sheet UnpluggedClapton
A1: Column1 | B1: Column2 | C1: Column3
A2: 41,71 | B2: 41 | C2: 71
A3: 41,71 | B3: 41 | C3: 71
A4: 34,99 | B4: 34 | C4: 99
A5: 39,99 | B5: 39 | C5: 99
A6: 16,99 | B6: 16 | C6: 99
A7: 16,85 | B7: 16 | C7: 85
A8: 22,99 | B8: 22 | C8: 99
A9: 16,99 | B9: 16 | C9: 99
A10: 30,61 | B10: 30 | C10: 61
A11: 23,99 | B11: 23 | C11: 99
A12: 16,99 | B12: 16 | C12: 99
A13: 22,99 | B13: 22 | C13: 99
... A17: 26,99 | B17: 26 | C17: 99
